Workbook

Sheet Sheet1
A3: Row Labels | B3: Sum of Total: Disability Compensation Recipients
A4: Texas | B4: 682628
A5: Florida | B5: 538014
A6: California | B6: 502173
A7: North Carolina | B7: 286763
A8: Virginia | B8: 275063
A9: Georgia | B9: 273766
A10: Ohio | B10: 191332
A11: Washington | B11: 173242
A12: Pennsylvania | B12: 171698
A13: Tennessee | B13: 168911
A14: Arizona | B14: 159063
A15: South Carolina | B15: 155553
... A19: Grand Total | B19: 4017660
A20: Real County? | B20: TRUE
A22: Row Labels | B22: Sum of Total: Disability Compensation Recipients
A23: San Diego, California | B23: 98159
A24: Bexar, Texas | B24: 95255
A25: Maricopa, Arizona | B25: 78855
A26: Los Angeles, California | B26: 73230
A27: Harris, Texas | B27: 61160
A28: Clark, Nevada | B28: 58508
A29: El Paso, Colorado | B29: 52489
A30: Riverside, California | B30: 50395
A31: Tarrant, Texas | B31: 42439
A32: Hillsborough, Florida | B32: 42212
A33: Bell, Texas | B33: 39929
A34: Duval, Florida | B34: 37487
... A38: Grand Total | B38: 830945

Sheet Dashboard
A1: DASHBOARD
A4: Total Recipients Nationwide | B4: Top State | C4: % Rated 70% or Higher
A5: =SUM(fy2025_disability_analysis_by_c!D2:D3149) -> 6331627 | B5: Texas | C5: =(Table2[[#This Row],[SUM]]+Sheet2!B6)/SUM(Table2[SUM]) -> 0.58721524

Sheet Sheet2
A1: SCD RANGE | B1: SUM | C1: % of Total
A2: 0% to 20% | B2: =SUM(fy2025_disability_analysis_by_c!E:E) -> 1218210 | C2: =(B2/SUM(B2:B6)) -> 0.19259238
A3: 30% to 40% | B3: =SUM(fy2025_disability_analysis_by_c!F:F) -> 663882 | C3: =(B3/SUM(B2:B6)) -> 0.10495614
A4: 50% to 60% | B4: =SUM(fy2025_disability_analysis_by_c!G:G) -> 728907 | C4: =(B4/SUM(B2:B6)) -> 0.11523624
A5: 70% to 90% | B5: =SUM(fy2025_disability_analysis_by_c!H:H) -> 1868474 | C5: =(B5/SUM(B2:B6)) -> 0.29539559
A6: 1 | B6: =SUM(fy2025_disability_analysis_by_c!I:I) -> 1845855 | C6: =(B6/SUM(B2:B6)) -> 0.29181965

Sheet fy2025_disability_analysis_by_c
A1: FIPS code | B1: State | C1: County Name | D1: Total: Disability Compensation Recipients | E1: SCD rating: 0% to 20% | F1: SCD rating: 30% to 40% | G1: SCD rating: 50% to 60% | H1: SCD rating: 70% to 90% | I1: SCD rating: 100% | J1: Age: 17-44 | K1: Age: 45-64 | L1: Age: 65 or older | M1: Male | N1: Female | O1: State,County | P1: Real County?
A2: 45001 | B2: South Carolina | C2: Abbeville | D2: 637 | E2: 107 | F2: 51 | G2: 82 | H2: 198 | I2: 199 | J2: 119 | K2: 196 | L2: 322 | M2: 575 | N2: 62 | O2: Abbeville, South Carolina | P2: =NOT(OR(Table1[[#This Row],[State]]="Other Foreign Countries", Table1[[#This Row],[State]]="Unknown", Table1[[#This Row],[State]]="Puerto Rico all counties")) -> TRUE
A3: 22001 | B3: Louisiana | C3: Acadia | D3: 867 | E3: 183 | F3: 92 | G3: 108 | H3: 250 | I3: 234 | J3: 226 | K3: 278 | L3: 363 | M3: 805 | N3: 61 | O3: Acadia, Louisiana | P3: =NOT(OR(Table1[[#This Row],[State]]="Other Foreign Countries", Table1[[#This Row],[State]]="Unknown", Table1[[#This Row],[State]]="Puerto Rico all counties")) -> TRUE
A4: 51001 | B4: Virginia | C4: Accomack | D4: 715 | E4: 133 | F4: 77 | G4: 101 | H4: 218 | I4: 186 | J4: 153 | K4: 250 | L4: 312 | M4: 626 | N4: 89 | O4: Accomack, Virginia | P4: =NOT(OR(Table1[[#This Row],[State]]="Other Foreign Countries", Table1[[#This Row],[State]]="Unknown", Table1[[#This Row],[State]]="Puerto Rico all counties")) -> TRUE
A5: 16001 | B5: Idaho | C5: Ada | D5: 13151 | E5: 2830 | F5: 1666 | G5: 1798 | H5: 3942 | I5: 2915 | J5: 4267 | K5: 4305 | L5: 4579 | M5: 11656 | N5: 1492 | O5: Ada, Idaho | P5: =NOT(OR(Table1[[#This Row],[State]]="Other Foreign Countries", Table1[[#This Row],[State]]="Unknown", Table1[[#This Row],[State]]="Puerto Rico all counties")) -> TRUE
A6: 19001 | B6: Iowa | C6: Adair | D6: 148 | E6: 37 | F6: 23 | G6: 13 | H6: 49 | I6: 26 | J6: 27 | K6: 37 | L6: 84 | O6: Adair, Iowa | P6: =NOT(OR(Table1[[#This Row],[State]]="Other Foreign Countries", Table1[[#This Row],[State]]="Unknown", Table1[[#This Row],[State]]="Puerto Rico all counties")) -> TRUE
A7: 21001 | B7: Kentucky | C7: Adair | D7: 339 | E7: 73 | F7: 33 | G7: 45 | H7: 103 | I7: 85 | J7: 79 | K7: 103 | L7: 157 | M7: 311 | N7: 28 | O7: Adair, Kentucky | P7: =NOT(OR(Table1[[#This Row],[State]]="Other Foreign Countries", Table1[[#This Row],[State]]="Unknown", Table1[[#This Row],[State]]="Puerto Rico all counties")) -> TRUE
A8: 29001 | B8: Missouri | C8: Adair | D8: 422 | E8: 136 | F8: 45 | G8: 44 | H8: 115 | I8: 82 | J8: 100 | K8: 128 | L8: 194 | M8: 383 | N8: 39 | O8: Adair, Missouri | P8: =NOT(OR(Table1[[#This Row],[State]]="Other Foreign Countries", Table1[[#This Row],[State]]="Unknown", Table1[[#This Row],[State]]="Puerto Rico all counties")) -> TRUE
A9: 40001 | B9: Oklahoma | C9: Adair | D9: 397 | E9: 84 | F9: 33 | G9: 44 | H9: 138 | I9: 98 | J9: 85 | K9: 110 | L9: 202 | M9: 373 | N9: 24 | O9: Adair, Oklahoma | P9: =NOT(OR(Table1[[#This Row],[State]]="Other Foreign Countries", Table1[[#This Row],[State]]="Unknown", Table1[[#This Row],[State]]="Puerto Rico all counties")) -> TRUE
A10: 8001 | B10: Colorado | C10: Adams | D10: 7698 | E10: 1590 | F10: 978 | G10: 1022 | H10: 2396 | I10: 1712 | J10: 3220 | K10: 2164 | L10: 2314 | M10: 6701 | N10: 997 | O10: Adams, Colorado | P10: =NOT(OR(Table1[[#This Row],[State]]="Other Foreign Countries", Table1[[#This Row],[State]]="Unknown", Table1[[#This Row],[State]]="Puerto Rico all counties")) -> TRUE
A11: 16003 | B11: Idaho | C11: Adams | D11: 158 | E11: 38 | F11: 26 | G11: 20 | H11: 46 | I11: 28 | J11: 30 | K11: 46 | L11: 82 | M11: 140 | N11: 18 | O11: Adams, Idaho | P11: =NOT(OR(Table1[[#This Row],[State]]="Other Foreign Countries", Table1[[#This Row],[State]]="Unknown", Table1[[#This Row],[State]]="Puerto Rico all counties")) -> TRUE
A12: 17001 | B12: Illinois | C12: Adams | D12: 1297 | E12: 283 | F12: 132 | G12: 148 | H12: 372 | I12: 362 | J12: 352 | K12: 334 | L12: 611 | M12: 1204 | N12: 93 | O12: Adams, Illinois | P12: =NOT(OR(Table1[[#This Row],[State]]="Other Foreign Countries", Table1[[#This Row],[State]]="Unknown", Table1[[#This Row],[State]]="Puerto Rico all counties")) -> TRUE
A13: 18001 | B13: Indiana | C13: Adams | D13: 407 | E13: 147 | F13: 75 | G13: 54 | H13: 89 | I13: 42 | J13: 85 | K13: 97 | L13: 225 | M13: 380 | N13: 27 | O13: Adams, Indiana | P13: =NOT(OR(Table1[[#This Row],[State]]="Other Foreign Countries", Table1[[#This Row],[State]]="Unknown", Table1[[#This Row],[State]]="Puerto Rico all counties")) -> TRUE
A14: 19003 | B14: Iowa | C14: Adams | D14: 59 | E14: 17 | G14: 15 | I14: 12 | J14: 10 | K14: 17 | L14: 32 | O14: Adams, Iowa | P14: =NOT(OR(Table1[[#This Row],[State]]="Other Foreign Countries", Table1[[#This Row],[State]]="Unknown", Table1[[#This Row],[State]]="Puerto Rico all counties")) -> TRUE
A15: 28001 | B15: Mississippi | C15: Adams | D15: 519 | E15: 75 | F15: 46 | G15: 55 | H15: 182 | I15: 161 | J15: 73 | K15: 159 | L15: 287 | M15: 448 | N15: 71 | O15: Adams, Mississippi | P15: =NOT(OR(Table1[[#This Row],[State]]="Other Foreign Countries", Table1[[#This Row],[State]]="Unknown", Table1[[#This Row],[State]]="Puerto Rico all counties")) -> TRUE
A16: 31001 | B16: Nebraska | C16: Adams | D16: 688 | E16: 278 | F16: 77 | G16: 81 | H16: 145 | I16: 107 | J16: 129 | K16: 153 | L16: 406 | M16: 639 | N16: 49 | O16: Adams, Nebraska | P16: =NOT(OR(Table1[[#This Row],[State]]="Other Foreign Countries", Table1[[#This Row],[State]]="Unknown", Table1[[#This Row],[State]]="Puerto Rico all counties")) -> TRUE
A17: 38001 | B17: North Dakota | C17: Adams | D17: 44 | E17: 13 | H17: 12 | L17: 30 | O17: Adams, North Dakota | P17: =NOT(OR(Table1[[#This Row],[State]]="Other Foreign Countries", Table1[[#This Row],[State]]="Unknown", Table1[[#This Row],[State]]="Puerto Rico all counties")) -> TRUE
A18: 39001 | B18: Ohio | C18: Adams | D18: 538 | E18: 156 | F18: 65 | G18: 80 | H18: 127 | I18: 110 | J18: 114 | K18: 144 | L18: 280 | M18: 511 | N18: 27 | O18: Adams, Ohio | P18: =NOT(OR(Table1[[#This Row],[State]]="Other Foreign Countries", Table1[[#This Row],[State]]="Unknown", Table1[[#This Row],[State]]="Puerto Rico all counties")) -> TRUE
A19: 42001 | B19: Pennsylvania | C19: Adams | D19: 1888 | E19: 418 | F19: 243 | G19: 258 | H19: 538 | I19: 431 | J19: 490 | K19: 599 | L19: 799 | M19: 1640 | N19: 248 | O19: Adams, Pennsylvania | P19: =NOT(OR(Table1[[#This Row],[State]]="Other Foreign Countries", Table1[[#This Row],[State]]="Unknown", Table1[[#This Row],[State]]="Puerto Rico all counties")) -> TRUE
A20: 53001 | B20: Washington | C20: Adams | D20: 140 | E20: 32 | F20: 15 | G20: 18 | H20: 36 | I20: 39 | J20: 45 | K20: 33 | L20: 62 | M20: 125 | N20: 15 | O20: Adams, Washington | P20: =NOT(OR(Table1[[#This Row],[State]]="Other Foreign Countries", Table1[[#This Row],[State]]="Unknown", Table1[[#This Row],[State]]="Puerto Rico all counties")) -> TRUE
A21: 55001 | B21: Wisconsin | C21: Adams | D21: 669 | E21: 166 | F21: 72 | G21: 94 | H21: 166 | I21: 171 | J21: 100 | K21: 179 | L21: 390 | M21: 624 | N21: 45 | O21: Adams, Wisconsin | P21: =NOT(OR(Table1[[#This Row],[State]]="Other Foreign Countries", Table1[[#This Row],[State]]="Unknown", Table1[[#This Row],[State]]="Puerto Rico all counties")) -> TRUE
A22: 50001 | B22: Vermont | C22: Addison | D22: 423 | E22: 110 | F22: 53 | G22: 50 | H22: 118 | I22: 92 | J22: 102 | K22: 123 | L22: 198 | M22: 384 | N22: 39 | O22: Addison, Vermont | P22: =NOT(OR(Table1[[#This Row],[State]]="Other Foreign Countries", Table1[[#This Row],[State]]="Unknown", Table1[[#This Row],[State]]="Puerto Rico all counties")) -> TRUE
A23: 45003 | B23: South Carolina | C23: Aiken | D23: 5544 | E23: 807 | F23: 577 | G23: 665 | H23: 1785 | I23: 1710 | J23: 1612 | K23: 2019 | L23: 1913 | M23: 4678 | N23: 865 | O23: Aiken, South Carolina | P23: =NOT(OR(Table1[[#This Row],[State]]="Other Foreign Countries", Table1[[#This Row],[State]]="Unknown", Table1[[#This Row],[State]]="Puerto Rico all counties")) -> TRUE
A24: 27001 | B24: Minnesota | C24: Aitkin | D24: 675 | E24: 302 | F24: 78 | G24: 70 | H24: 127 | I24: 98 | J24: 57 | K24: 133 | L24: 485 | M24: 640 | N24: 34 | O24: Aitkin, Minnesota | P24: =NOT(OR(Table1[[#This Row],[State]]="Other Foreign Countries", Table1[[#This Row],[State]]="Unknown", Table1[[#This Row],[State]]="Puerto Rico all counties")) -> TRUE
A25: 12001 | B25: Florida | C25: Alachua | D25: 5640 | E25: 1133 | F25: 618 | G25: 695 | H25: 1621 | I25: 1573 | J25: 1476 | K25: 1876 | L25: 2288 | M25: 4834 | N25: 803 | O25: Alachua, Florida | P25: =NOT(OR(Table1[[#This Row],[State]]="Other Foreign Countries", Table1[[#This Row],[State]]="Unknown", Table1[[#This Row],[State]]="Puerto Rico all counties")) -> TRUE
A26: 37001 | B26: North Carolina | C26: Alamance | D26: 3179 | E26: 569 | F26: 332 | G26: 375 | H26: 998 | I26: 905 | J26: 900 | K26: 1036 | L26: 1243 | M26: 2743 | N26: 435 | O26: Alamance, North Carolina | P26: =NOT(OR(Table1[[#This Row],[State]]="Other Foreign Countries", Table1[[#This Row],[State]]="Unknown", Table1[[#This Row],[State]]="Puerto Rico all counties")) -> TRUE
A27: 6001 | B27: California | C27: Alameda | D27: 10203 | E27: 2196 | F27: 1143 | G27: 1238 | H27: 2911 | I27: 2715 | J27: 3321 | K27: 2698 | L27: 4184 | M27: 9039 | N27: 1162 | O27: Alameda, California | P27: =NOT(OR(Table1[[#This Row],[State]]="Other Foreign Countries", Table1[[#This Row],[State]]="Unknown", Table1[[#This Row],[State]]="Puerto Rico all counties")) -> TRUE
A28: 8003 | B28: Colorado | C28: Alamosa | D28: 282 | E28: 54 | F28: 27 | G28: 35 | H28: 88 | I28: 78 | J28: 73 | K28: 81 | L28: 128 | M28: 255 | N28: 27 | O28: Alamosa, Colorado | P28: =NOT(OR(Table1[[#This Row],[State]]="Other Foreign Countries", Table1[[#This Row],[State]]="Unknown", Table1[[#This Row],[State]]="Puerto Rico all counties")) -> TRUE
A29: 36001 | B29: New York | C29: Albany | D29: 3069 | E29: 748 | F29: 389 | G29: 381 | H29: 850 | I29: 701 | J29: 825 | K29: 871 | L29: 1373 | M29: 2724 | N29: 344 | O29: Albany, New York | P29: =NOT(OR(Table1[[#This Row],[State]]="Other Foreign Countries", Table1[[#This Row],[State]]="Unknown", Table1[[#This Row],[State]]="Puerto Rico all counties")) -> TRUE
... A33: 28003 | B33: Mississippi | C33: Alcorn | D33: 592 | E33: 132 | F33: 72 | G33: 59 | H33: 180 | I33: 149 | J33: 147 | K33: 167 | L33: 278 | M33: 547 | N33: 45 | O33: Alcorn, Mississippi | P33: =NOT(OR(Table1[[#This Row],[State]]="Other Foreign Countries", Table1[[#This Row],[State]]="Unknown", Table1[[#This Row],[State]]="Puerto Rico all counties")) -> TRUE
A34: 2013 | B34: Alaska | C34: Aleutians East | O34: Aleutians East, Alaska | P34: =NOT(OR(Table1[[#This Row],[State]]="Other Foreign Countries", Table1[[#This Row],[State]]="Unknown", Table1[[#This Row],[State]]="Puerto Rico all counties")) -> TRUE
A35: 2016 | B35: Alaska | C35: Aleutians West | D35: 28 | J35: 11 | O35: Aleutians West, Alaska | P35: =NOT(OR(Table1[[#This Row],[State]]="Other Foreign Countries", Table1[[#This Row],[State]]="Unknown", Table1[[#This Row],[State]]="Puerto Rico all counties")) -> TRUE
A36: 17003 | B36: Illinois | C36: Alexander | D36: 125 | E36: 22 | F36: 16 | G36: 16 | H36: 42 | I36: 29 | J36: 12 | K36: 40 | L36: 73 | M36: 114 | N36: 11 | O36: Alexander, Illinois | P36: =NOT(OR(Table1[[#This Row],[State]]="Other Foreign Countries", Table1[[#This Row],[State]]="Unknown", Table1[[#This Row],[State]]="Puerto Rico all counties")) -> TRUE
A37: 37003 | B37: North Carolina | C37: Alexander | D37: 706 | E37: 142 | F37: 76 | G37: 94 | H37: 211 | I37: 183 | J37: 166 | K37: 177 | L37: 363 | M37: 654 | N37: 52 | O37: Alexander, North Carolina | P37: =NOT(OR(Table1[[#This Row],[State]]="Other Foreign Countries", Table1[[#This Row],[State]]="Unknown", Table1[[#This Row],[State]]="Puerto Rico all counties")) -> TRUE
A38: 51510 | B38: Virginia | C38: Alexandria City | D38: 4621 | E38: 616 | F38: 570 | G38: 618 | H38: 1370 | I38: 1447 | J38: 1945 | K38: 1891 | L38: 785 | M38: 3468 | N38: 1153 | O38: Alexandria City, Virginia | P38: =NOT(OR(Table1[[#This Row],[State]]="Other Foreign Countries", Table1[[#This Row],[State]]="Unknown", Table1[[#This Row],[State]]="Puerto Rico all counties")) -> TRUE
A39: 40003 | B39: Oklahoma | C39: Alfalfa | D39: 111 | E39: 31 | F39: 18 | G39: 12 | H39: 28 | I39: 22 | J39: 23 | K39: 41 | L39: 47 | O39: Alfalfa, Oklahoma | P39: =NOT(OR(Table1[[#This Row],[State]]="Other Foreign Countries", Table1[[#This Row],[State]]="Unknown", Table1[[#This Row],[State]]="Puerto Rico all counties")) -> TRUE
A40: 26003 | B40: Michigan | C40: Alger | D40: 287 | E40: 80 | F40: 34 | G40: 37 | H40: 77 | I40: 59 | J40: 40 | K40: 90 | L40: 157 | M40: 266 | N40: 21 | O40: Alger, Michigan | P40: =NOT(OR(Table1[[#This Row],[State]]="Other Foreign Countries", Table1[[#This Row],[State]]="Unknown", Table1[[#This Row],[State]]="Puerto Rico all counties")) -> TRUE
A41: 19005 | B41: Iowa | C41: Allamakee | D41: 222 | E41: 55 | F41: 32 | G41: 26 | H41: 55 | I41: 54 | J41: 46 | K41: 56 | L41: 120 | M41: 203 | N41: 19 | O41: Allamakee, Iowa | P41: =NOT(OR(Table1[[#This Row],[State]]="Other Foreign Countries", Table1[[#This Row],[State]]="Unknown", Table1[[#This Row],[State]]="Puerto Rico all counties")) -> TRUE
A42: 26005 | B42: Michigan | C42: Allegan | D42: 1452 | E42: 275 | F42: 179 | G42: 206 | H42: 435 | I42: 357 | J42: 480 | K42: 381 | L42: 591 | M42: 1322 | N42: 130 | O42: Allegan, Michigan | P42: =NOT(OR(Table1[[#This Row],[State]]="Other Foreign Countries", Table1[[#This Row],[State]]="Unknown", Table1[[#This Row],[State]]="Puerto Rico all counties")) -> TRUE
A43: 24001 | B43: Maryland | C43: Allegany | D43: 1071 | E43: 224 | F43: 133 | G43: 150 | H43: 298 | I43: 266 | J43: 254 | K43: 330 | L43: 487 | M43: 1004 | N43: 67 | O43: Allegany, Maryland | P43: =NOT(OR(Table1[[#This Row],[State]]="Other Foreign Countries", Table1[[#This Row],[State]]="Unknown", Table1[[#This Row],[State]]="Puerto Rico all counties")) -> TRUE
...
